<?xml version="1.0" encoding="UTF-8"?>
<!-- Generated by org.testng.reporters.JUnitReportReporter -->
<testsuite name="BusinessLogic.RetryOnlyFailedTests" tests="9" time="0.015" ignored="0" failures="2" timestamp="28 Oct 2022 06:07:06 GMT" skipped="6" hostname="DESKTOP-RJ3L28L" errors="0">
  <testcase name="test2" time="0.001" classname="BusinessLogic.RetryOnlyFailedTests">
    <failure type="java.lang.AssertionError" message="Addition Problem! 2+2 must be 4!
 expected [3] but found [4]">
      <![CDATA[java.lang.AssertionError: Addition Problem! 2+2 must be 4!
 expected [3] but found [4]
	at org.testng.Assert.fail(Assert.java:94)
	at org.testng.Assert.failNotEquals(Assert.java:513)
	at org.testng.Assert.assertEqualsImpl(Assert.java:135)
	at org.testng.Assert.assertEquals(Assert.java:116)
	at org.testng.Assert.assertEquals(Assert.java:389)
	at BusinessLogic.RetryOnlyFailedTests.test2(RetryOnlyFailedTests.java:16)
	at sun.reflect.NativeMethodAccessorImpl.invoke0(Native Method)
	at sun.reflect.NativeMethodAccessorImpl.invoke(NativeMethodAccessorImpl.java:62)
	at sun.reflect.DelegatingMethodAccessorImpl.invoke(DelegatingMethodAccessorImpl.java:43)
	at java.lang.reflect.Method.invoke(Method.java:498)
	at org.testng.internal.MethodInvocationHelper.invokeMethod(MethodInvocationHelper.java:104)
	at org.testng.internal.Invoker.invokeMethod(Invoker.java:645)
	at org.testng.internal.Invoker.retryFailed(Invoker.java:998)
	at org.testng.internal.Invoker.invokeTestMethods(Invoker.java:1200)
	at org.testng.internal.TestMethodWorker.invokeTestMethods(TestMethodWorker.java:129)
	at org.testng.internal.TestMethodWorker.run(TestMethodWorker.java:112)
	at org.testng.TestRunner.privateRun(TestRunner.java:756)
	at org.testng.TestRunner.run(TestRunner.java:610)
	at org.testng.SuiteRunner.runTest(SuiteRunner.java:387)
	at org.testng.SuiteRunner.runSequentially(SuiteRunner.java:382)
	at org.testng.SuiteRunner.privateRun(SuiteRunner.java:340)
	at org.testng.SuiteRunner.run(SuiteRunner.java:289)
	at org.testng.SuiteRunnerWorker.runSuite(SuiteRunnerWorker.java:52)
	at org.testng.SuiteRunnerWorker.run(SuiteRunnerWorker.java:86)
	at org.testng.TestNG.runSuitesSequentially(TestNG.java:1293)
	at org.testng.TestNG.runSuitesLocally(TestNG.java:1218)
	at org.testng.TestNG.runSuites(TestNG.java:1133)
	at org.testng.TestNG.run(TestNG.java:1104)
	at org.testng.remote.AbstractRemoteTestNG.run(AbstractRemoteTestNG.java:115)
	at org.testng.remote.RemoteTestNG.initAndRun(RemoteTestNG.java:251)
	at org.testng.remote.RemoteTestNG.main(RemoteTestNG.java:77)
]]>
    </failure>
  </testcase> <!-- test2 -->
  <testcase name="test1" time="0.009" classname="BusinessLogic.RetryOnlyFailedTests">
    <skipped/>
  </testcase> <!-- test1 -->
  <testcase name="test1" time="0.001" classname="BusinessLogic.RetryOnlyFailedTests">
    <skipped/>
  </testcase> <!-- test1 -->
  <testcase name="test2" time="0.001" classname="BusinessLogic.RetryOnlyFailedTests">
    <skipped/>
  </testcase> <!-- test2 -->
  <testcase name="test1" time="0.000" classname="BusinessLogic.RetryOnlyFailedTests">
    <skipped/>
  </testcase> <!-- test1 -->
  <testcase name="test1" time="0.000" classname="BusinessLogic.RetryOnlyFailedTests">
    <failure type="java.lang.AssertionError" message="Addition Problem! 2+2 must be 4!
 expected [5] but found [4]">
      <![CDATA[java.lang.AssertionError: Addition Problem! 2+2 must be 4!
 expected [5] but found [4]
	at org.testng.Assert.fail(Assert.java:94)
	at org.testng.Assert.failNotEquals(Assert.java:513)
	at org.testng.Assert.assertEqualsImpl(Assert.java:135)
	at org.testng.Assert.assertEquals(Assert.java:116)
	at org.testng.Assert.assertEquals(Assert.java:389)
	at BusinessLogic.RetryOnlyFailedTests.test1(RetryOnlyFailedTests.java:10)
	at sun.reflect.NativeMethodAccessorImpl.invoke0(Native Method)
	at sun.reflect.NativeMethodAccessorImpl.invoke(NativeMethodAccessorImpl.java:62)
	at sun.reflect.DelegatingMethodAccessorImpl.invoke(DelegatingMethodAccessorImpl.java:43)
	at java.lang.reflect.Method.invoke(Method.java:498)
	at org.testng.internal.MethodInvocationHelper.invokeMethod(MethodInvocationHelper.java:104)
	at org.testng.internal.Invoker.invokeMethod(Invoker.java:645)
	at org.testng.internal.Invoker.retryFailed(Invoker.java:998)
	at org.testng.internal.Invoker.invokeTestMethods(Invoker.java:1200)
	at org.testng.internal.TestMethodWorker.invokeTestMethods(TestMethodWorker.java:129)
	at org.testng.internal.TestMethodWorker.run(TestMethodWorker.java:112)
	at org.testng.TestRunner.privateRun(TestRunner.java:756)
	at org.testng.TestRunner.run(TestRunner.java:610)
	at org.testng.SuiteRunner.runTest(SuiteRunner.java:387)
	at org.testng.SuiteRunner.runSequentially(SuiteRunner.java:382)
	at org.testng.SuiteRunner.privateRun(SuiteRunner.java:340)
	at org.testng.SuiteRunner.run(SuiteRunner.java:289)
	at org.testng.SuiteRunnerWorker.runSuite(SuiteRunnerWorker.java:52)
	at org.testng.SuiteRunnerWorker.run(SuiteRunnerWorker.java:86)
	at org.testng.TestNG.runSuitesSequentially(TestNG.java:1293)
	at org.testng.TestNG.runSuitesLocally(TestNG.java:1218)
	at org.testng.TestNG.runSuites(TestNG.java:1133)
	at org.testng.TestNG.run(TestNG.java:1104)
	at org.testng.remote.AbstractRemoteTestNG.run(AbstractRemoteTestNG.java:115)
	at org.testng.remote.RemoteTestNG.initAndRun(RemoteTestNG.java:251)
	at org.testng.remote.RemoteTestNG.main(RemoteTestNG.java:77)
]]>
    </failure>
  </testcase> <!-- test1 -->
  <testcase name="test2" time="0.001" classname="BusinessLogic.RetryOnlyFailedTests">
    <skipped/>
  </testcase> <!-- test2 -->
  <testcase name="test2" time="0.001" classname="BusinessLogic.RetryOnlyFailedTests">
    <skipped/>
  </testcase> <!-- test2 -->
  <testcase name="test3" time="0.001" classname="BusinessLogic.RetryOnlyFailedTests"/>
</testsuite> <!-- BusinessLogic.RetryOnlyFailedTests -->
